Workbook
Name Cinematography_SemI_A: DV_Helper!$A$1:$A$8
Name Cinematography_SemI_B: DV_Helper!$A$9:$A$16
Name Cinematography_SemI_C: DV_Helper!$A$17:$A$24
Name Cinematography_SemI_D: DV_Helper!$A$25:$A$32
Name Cinematography_SemII_A: DV_Helper!$A$193:$A$200
Name Cinematography_SemII_B: DV_Helper!$A$201:$A$208
Name Cinematography_SemII_C: DV_Helper!$A$209:$A$216
Name Cinematography_SemII_D: DV_Helper!$A$217:$A$224
Name Cinematography_SemIII_A: DV_Helper!$A$385:$A$392
Name Cinematography_SemIII_B: DV_Helper!$A$393:$A$400
Name Cinematography_SemIII_C: DV_Helper!$A$401:$A$408
Name Cinematography_SemIII_D: DV_Helper!$A$409:$A$416
Name Cinematography_SemIV_A: DV_Helper!$A$610:$A$617
Name Cinematography_SemIV_B: DV_Helper!$A$618:$A$625
Name Cinematography_SemIV_C: DV_Helper!$A$626:$A$633
Name Cinematography_SemIV_D: DV_Helper!$A$634:$A$641
Name Cinematography_SemV_A: DV_Helper!$A$804:$A$811
Name Cinematography_SemV_B: DV_Helper!$A$812:$A$819
Name Cinematography_SemV_C: DV_Helper!$A$820:$A$827
Name Cinematography_SemV_D: DV_Helper!$A$828:$A$835
Name Cinematography_SemVI_A: DV_Helper!$A$1024:$A$1031
Name Cinematography_SemVI_B: DV_Helper!$A$1032:$A$1039
Name Cinematography_SemVI_C: DV_Helper!$A$1040:$A$1047
Name Cinematography_SemVI_D: DV_Helper!$A$1048:$A$1055
Name Creative_A: Lists!$FJ$2:$FJ$9
Name Creative_B: Lists!$FK$2:$FK$9
Name Creative_C: Lists!$FL$2:$FL$9
Name Creative_D: Lists!$FM$2:$FM$9
Name Direction_SemI_A: DV_Helper!$A$33:$A$40
Name Direction_SemI_B: DV_Helper!$A$41:$A$48
Name Direction_SemI_C: DV_Helper!$A$49:$A$56
Name Direction_SemI_D: DV_Helper!$A$57:$A$64
Name Direction_SemII_A: DV_Helper!$A$225:$A$232
Name Direction_SemII_B: DV_Helper!$A$233:$A$240
Name Direction_SemII_C: DV_Helper!$A$241:$A$248
Name Direction_SemII_D: DV_Helper!$A$249:$A$256
Name Direction_SemIII_A: DV_Helper!$A$417:$A$424
Name Direction_SemIII_B: DV_Helper!$A$425:$A$432
Name Direction_SemIII_C: DV_Helper!$A$433:$A$440
Name Direction_SemIII_D: DV_Helper!$A$441:$A$448
Name Direction_SemIV_D: DV_Helper!$A$642:$A$642
Name Direction_SemV_A: DV_Helper!$A$836:$A$837
Name Direction_SemV_B: DV_Helper!$A$838:$A$845
Name Direction_SemV_C: DV_Helper!$A$846:$A$853
Name Direction_SemV_D: DV_Helper!$A$854:$A$861
Name Direction_SemVI_D: DV_Helper!$A$1056:$A$1057
Name Editing_SemI_A: DV_Helper!$A$65:$A$72
Name Editing_SemI_B: DV_Helper!$A$73:$A$80
Name Editing_SemI_C: DV_Helper!$A$81:$A$88
Name Editing_SemI_D: DV_Helper!$A$89:$A$96
Name Editing_SemII_A: DV_Helper!$A$257:$A$264
Name Editing_SemII_B: DV_Helper!$A$265:$A$272
Name Editing_SemII_C: DV_Helper!$A$273:$A$280
Name Editing_SemII_D: DV_Helper!$A$281:$A$288
Name Editing_SemIII_A: DV_Helper!$A$449:$A$456
Name Editing_SemIII_B: DV_Helper!$A$457:$A$464
Name Editing_SemIII_C: DV_Helper!$A$465:$A$472
Name Editing_SemIII_D: DV_Helper!$A$473:$A$480
Name Editing_SemIV_A: DV_Helper!$A$643:$A$650
Name Editing_SemIV_B: DV_Helper!$A$651:$A$658

Sheet Evaluation Sheet
A1: B.A. Filmmaking – Integrated Final Working System
A2: For Excel: grade and comment dropdowns work directly. For Google Sheets: use Comment Matrix to review combinations and apply dropdowns natively if needed.
A3: Student Name | B3: Roll No. | C3: Department / Specialisation | D3: Sem I Screenwriting Grade | E3: Sem I Screenwriting Comment | F3: Sem I Direction Grade | G3: Sem I Direction Comment | H3: Sem I Production Grade | I3: Sem I Production Comment | J3: Sem I Cine Grade | K3: Sem I Cine Comment | L3: Sem I Sound Grade | M3: Sem I Sound Comment | N3: Sem I Edit Grade | O3: Sem I Edit Comment | P3: Sem II Screenwriting Grade | Q3: Sem II Screenwriting Comment | R3: Sem II Direction Grade | S3: Sem II Direction Comment | T3: Sem II Production Grade | U3: Sem II Production Comment | V3: Sem II Cine Grade | W3: Sem II Cine Comment | X3: Sem II Sound Grade | Y3: Sem II Sound Comment | Z3: Sem II Edit Grade | AA3: Sem II Edit Comment | AB3: Sem III Specialisation Grade | AC3: Sem III Specialisation Comment | AD3: Sem III Direction Grade | AE3: Sem III Direction Comment | AF3: Sem III Production Grade | AG3: Sem III Production Comment | AH3: Sem IV Specialisation Grade | AI3: Sem IV Specialisation Comment | AJ3: Sem IV Direction Grade | AK3: Sem IV Direction Comment | AL3: Sem IV Production Grade | AM3: Sem IV Production Comment | AN3: Sem V Specialisation Grade | AO3: Sem V Specialisation Comment | AP3: Sem V Direction Grade | AQ3: Sem V Direction Comment | AR3: Sem V Production Grade | AS3: Sem V Production Comment | AT3: Sem VI Specialisation Grade | AU3: Sem VI Specialisation Comment | AV3: Sem VI Direction Grade | AW3: Sem VI Direction Comment | AX3: Sem VI Production Grade | AY3: Sem VI Production Comment | AZ3: Creative Comment | BA3: Technical Comment | BB3: Professional Comment | BC3: Final % | BD3: Final Grade | BE3: Portfolio URL
A4: SRIRAM | B4: 1 | C4: Cinematography | D4: C | E4: Needs stronger control over narrative progression to meet foundation writing expectations more consistently. | F4: C | G4: Reflects basic narrative control, though consistency against foundational understanding expectations needs improvement. | H4: A | I4: Production: Successfully achieves semi-aligned outcomes that bridge the gap between creative experimentation and disciplined production. | J4: C | K4: Cinematography: Camera angles are used without clear purpose or variation. | L4: D | M4: Sound Design: Requires significant improvement in Portable Audio Recording Devices. | N4: C | O4: Editing: Shot lengths feel random; pacing does not support mood or engagement. | P4: C | Q4: Screenwriting: Conflict is underdeveloped or unclear, reducing engagement. | R4: D | S4: Direction: Fails to use visualisation tools required for planning scenes. | T4: D | U4: Production: Significant gaps in foundational knowledge are hindering the ability to complete Semester tasks effectively. | V4: B | W4: Cinematography: Indicates some connection between emotion and movement, though not fully developed. | X4: C | Y4: Sound Design: Basic capability in Sound Recording & Sound Editing of Dialogue Scenes. | Z4: C | AA4: Editing: Basic understanding present across dialogue, montage, and sound, but execution is inconsistent. | AB4: A | AC4: Cinematography: Executes camera movements with clear narrative intent, effectively supporting storytelling. | AD4: A | AE4: Direction: Demonstrates a strong documentary vision with clear thematic focus, while further deepening observational nuance. | AF4: B | AG4: Production: Demonstrates a successful grasp of advanced Sem concepts, applying them effectively to reach multifaceted outcomes. | AH4: D | AI4: Cinematography: Does not demonstrate understanding of color correction or visual continuity. | AJ4: A | AK4: Direction: Integrates all departments cohesively, though minor inconsistencies in tonal control can be improved. | AL4: B | AM4: Production: Demonstrates a solid grasp of professional-level tasks, successfully applying Sem theory to produce effective, high-quality outcomes. | AN4: C | AO4: Cinematography: Shows limited understanding of cinematography styles and their application. | AP4: A | AQ4: Direction: Shows excellent understanding of VOD storytelling dynamics, while pushing for more innovative visual treatment. | AR4: D | AS4: Production: Significant gaps in specialized knowledge are preventing the successful execution of advanced Semester production tasks. | AT4: D | AU4: Cinematography: Struggles to interpret and translate direction into cinematographic decisions. | AV4: C | AW4: Direction: Actor direction is inconsistent, affecting performance quality. | AX4: C | AY4: Production: Demonstrates the basic capability required to complete the capstone, though the final work lacks the depth of a specialized professional. | AZ4: Indicates basic narrative sensitivity, though consistency against professional readiness and final output expectations needs improvement. | BA4: Needs stronger control over tool command to meet professional readiness and final output expectations more consistently. | BB4: Requires better control over professional attitude to meet professional readiness and final output expectations more consistently. | BC4: =IFERROR((COUNTIF(D4:AX4,"A")*4+COUNTIF(D4:AX4,"B")*3+COUNTIF(D4:AX4,"C")*2+COUNTIF(D4:AX4,"D")*1)/(COUNTIF(D4:AX4,"A")+COUNTIF(D4:AX4,"B")+COUNTIF(D4:AX4,"C")+COUNTIF(D4:AX4,"D"))*25,"") -> 57.291667 | BD4: =IF(BC4="","",IF(BC4>=85,"A",IF(BC4>=70,"B",IF(BC4>=50,"C","D")))) -> C | BG4: =IF(D4="","",IF(D4="A",90,IF(D4="B",75,IF(D4="C",60,45)))) -> 60 | BH4: =IF(F4="","",IF(F4="A",90,IF(F4="B",75,IF(F4="C",60,45)))) -> 60 | BI4: =IF(H4="","",IF(H4="A",90,IF(H4="B",75,IF(H4="C",60,45)))) -> 90 | BJ4: =IF(J4="","",IF(J4="A",90,IF(J4="B",75,IF(J4="C",60,45)))) -> 60 | BK4: =IF(L4="","",IF(L4="A",90,IF(L4="B",75,IF(L4="C",60,45)))) -> 45 | BL4: =IF(N4="","",IF(N4="A",90,IF(N4="B",75,IF(N4="C",60,45)))) -> 60 | BM4: =IF(P4="","",IF(P4="A",90,IF(P4="B",75,IF(P4="C",60,45)))) -> 60 | BN4: =IF(R4="","",IF(R4="A",90,IF(R4="B",75,IF(R4="C",60,45)))) -> 45 | BO4: =IF(T4="","",IF(T4="A",90,IF(T4="B",75,IF(T4="C",60,45)))) -> 45 | BP4: =IF(V4="","",IF(V4="A",90,IF(V4="B",75,IF(V4="C",60,45)))) -> 75 | BQ4: =IF(X4="","",IF(X4="A",90,IF(X4="B",75,IF(X4="C",60,45)))) -> 60 | BR4: =IF(Z4="","",IF(Z4="A",90,IF(Z4="B",75,IF(Z4="C",60,45)))) -> 60 | BS4: =IF(AB4="","",IF(AB4="A",90,IF(AB4="B",75,IF(AB4="C",60,45)))) -> 90 | BT4: =IF(AD4="","",IF(AD4="A",90,IF(AD4="B",75,IF(AD4="C",60,45)))) -> 90 | BU4: =IF(AF4="","",IF(AF4="A",90,IF(AF4="B",75,IF(AF4="C",60,45)))) -> 75 | BV4: =IF(AH4="","",IF(AH4="A",90,IF(AH4="B",75,IF(AH4="C",60,45)))) -> 45 | BW4: =IF(AJ4="","",IF(AJ4="A",90,IF(AJ4="B",75,IF(AJ4="C",60,45)))) -> 90 | BX4: =IF(AL4="","",IF(AL4="A",90,IF(AL4="B",75,IF(AL4="C",60,45)))) -> 75 | BY4: =IF(AN4="","",IF(AN4="A",90,IF(AN4="B",75,IF(AN4="C",60,45)))) -> 60 | BZ4: =IF(AP4="","",IF(AP4="A",90,IF(AP4="B",75,IF(AP4="C",60,45)))) -> 90 | CA4: =IF(AR4="","",IF(AR4="A",90,IF(AR4="B",75,IF(AR4="C",60,45)))) -> 45 | CB4: =IF(AT4="","",IF(AT4="A",90,IF(AT4="B",75,IF(AT4="C",60,45)))) -> 45 | CC4: =IF(AV4="","",IF(AV4="A",90,IF(AV4="B",75,IF(AV4="C",60,45)))) -> 60 | CD4: =IF(AX4="","",IF(AX4="A",90,IF(AX4="B",75,IF(AX4="C",60,45)))) -> 60
A5: SISTLA | B5: 2 | H5: D | I5: Production: The final outcome shows limited alignment with the project requirements, necessitating a more focused approach to the brief. | T5: D | U5: Production: Requires significant improvement in fundamentals and execution for sem ii (5). | BC5: =IFERROR((COUNTIF(D5:AX5,"A")*4+COUNTIF(D5:AX5,"B")*3+COUNTIF(D5:AX5,"C")*2+COUNTIF(D5:AX5,"D")*1)/(COUNTIF(D5:AX5,"A")+COUNTIF(D5:AX5,"B")+COUNTIF(D5:AX5,"C")+COUNTIF(D5:AX5,"D"))*25,"") -> 25 | BD5: =IF(BC5="","",IF(BC5>=85,"A",IF(BC5>=70,"B",IF(BC5>=50,"C","D")))) -> D | BG5: =IF(D5="","",IF(D5="A",90,IF(D5="B",75,IF(D5="C",60,45)))) | BH5: =IF(F5="","",IF(F5="A",90,IF(F5="B",75,IF(F5="C",60,45)))) | BI5: =IF(H5="","",IF(H5="A",90,IF(H5="B",75,IF(H5="C",60,45)))) -> 45 | BJ5: =IF(J5="","",IF(J5="A",90,IF(J5="B",75,IF(J5="C",60,45)))) | BK5: =IF(L5="","",IF(L5="A",90,IF(L5="B",75,IF(L5="C",60,45)))) | BL5: =IF(N5="","",IF(N5="A",90,IF(N5="B",75,IF(N5="C",60,45)))) | BM5: =IF(P5="","",IF(P5="A",90,IF(P5="B",75,IF(P5="C",60,45)))) | BN5: =IF(R5="","",IF(R5="A",90,IF(R5="B",75,IF(R5="C",60,45)))) | BO5: =IF(T5="","",IF(T5="A",90,IF(T5="B",75,IF(T5="C",60,45)))) -> 45 | BP5: =IF(V5="","",IF(V5="A",90,IF(V5="B",75,IF(V5="C",60,45)))) | BQ5: =IF(X5="","",IF(X5="A",90,IF(X5="B",75,IF(X5="C",60,45)))) | BR5: =IF(Z5="","",IF(Z5="A",90,IF(Z5="B",75,IF(Z5="C",60,45)))) | BS5: =IF(AB5="","",IF(AB5="A",90,IF(AB5="B",75,IF(AB5="C",60,45)))) | BT5: =IF(AD5="","",IF(AD5="A",90,IF(AD5="B",75,IF(AD5="C",60,45)))) | BU5: =IF(AF5="","",IF(AF5="A",90,IF(AF5="B",75,IF(AF5="C",60,45)))) | BV5: =IF(AH5="","",IF(AH5="A",90,IF(AH5="B",75,IF(AH5="C",60,45)))) | BW5: =IF(AJ5="","",IF(AJ5="A",90,IF(AJ5="B",75,IF(AJ5="C",60,45)))) | BX5: =IF(AL5="","",IF(AL5="A",90,IF(AL5="B",75,IF(AL5="C",60,45)))) | BY5: =IF(AN5="","",IF(AN5="A",90,IF(AN5="B",75,IF(AN5="C",60,45)))) | BZ5: =IF(AP5="","",IF(AP5="A",90,IF(AP5="B",75,IF(AP5="C",60,45)))) | CA5: =IF(AR5="","",IF(AR5="A",90,IF(AR5="B",75,IF(AR5="C",60,45)))) | CB5: =IF(AT5="","",IF(AT5="A",90,IF(AT5="B",75,IF(AT5="C",60,45)))) | CC5: =IF(AV5="","",IF(AV5="A",90,IF(AV5="B",75,IF(AV5="C",60,45)))) | CD5: =IF(AX5="","",IF(AX5="A",90,IF(AX5="B",75,IF(AX5="C",60,45))))
A6: PRAVEEN | B6: 3 | BC6: =IFERROR((COUNTIF(D6:AX6,"A")*4+COUNTIF(D6:AX6,"B")*3+COUNTIF(D6:AX6,"C")*2+COUNTIF(D6:AX6,"D")*1)/(COUNTIF(D6:AX6,"A")+COUNTIF(D6:AX6,"B")+COUNTIF(D6:AX6,"C")+COUNTIF(D6:AX6,"D"))*25,"") | BD6: =IF(BC6="","",IF(BC6>=85,"A",IF(BC6>=70,"B",IF(BC6>=50,"C","D")))) | BG6: =IF(D6="","",IF(D6="A",90,IF(D6="B",75,IF(D6="C",60,45)))) | BH6: =IF(F6="","",IF(F6="A",90,IF(F6="B",75,IF(F6="C",60,45)))) | BI6: =IF(H6="","",IF(H6="A",90,IF(H6="B",75,IF(H6="C",60,45)))) | BJ6: =IF(J6="","",IF(J6="A",90,IF(J6="B",75,IF(J6="C",60,45)))) | BK6: =IF(L6="","",IF(L6="A",90,IF(L6="B",75,IF(L6="C",60,45)))) | BL6: =IF(N6="","",IF(N6="A",90,IF(N6="B",75,IF(N6="C",60,45)))) | BM6: =IF(P6="","",IF(P6="A",90,IF(P6="B",75,IF(P6="C",60,45)))) | BN6: =IF(R6="","",IF(R6="A",90,IF(R6="B",75,IF(R6="C",60,45)))) | BO6: =IF(T6="","",IF(T6="A",90,IF(T6="B",75,IF(T6="C",60,45)))) | BP6: =IF(V6="","",IF(V6="A",90,IF(V6="B",75,IF(V6="C",60,45)))) | BQ6: =IF(X6="","",IF(X6="A",90,IF(X6="B",75,IF(X6="C",60,45)))) | BR6: =IF(Z6="","",IF(Z6="A",90,IF(Z6="B",75,IF(Z6="C",60,45)))) | BS6: =IF(AB6="","",IF(AB6="A",90,IF(AB6="B",75,IF(AB6="C",60,45)))) | BT6: =IF(AD6="","",IF(AD6="A",90,IF(AD6="B",75,IF(AD6="C",60,45)))) | BU6: =IF(AF6="","",IF(AF6="A",90,IF(AF6="B",75,IF(AF6="C",60,45)))) | BV6: =IF(AH6="","",IF(AH6="A",90,IF(AH6="B",75,IF(AH6="C",60,45)))) | BW6: =IF(AJ6="","",IF(AJ6="A",90,IF(AJ6="B",75,IF(AJ6="C",60,45)))) | BX6: =IF(AL6="","",IF(AL6="A",90,IF(AL6="B",75,IF(AL6="C",60,45)))) | BY6: =IF(AN6="","",IF(AN6="A",90,IF(AN6="B",75,IF(AN6="C",60,45)))) | BZ6: =IF(AP6="","",IF(AP6="A",90,IF(AP6="B",75,IF(AP6="C",60,45)))) | CA6: =IF(AR6="","",IF(AR6="A",90,IF(AR6="B",75,IF(AR6="C",60,45)))) | CB6: =IF(AT6="","",IF(AT6="A",90,IF(AT6="B",75,IF(AT6="C",60,45)))) | CC6: =IF(AV6="","",IF(AV6="A",90,IF(AV6="B",75,IF(AV6="C",60,45)))) | CD6: =IF(AX6="","",IF(AX6="A",90,IF(AX6="B",75,IF(AX6="C",60,45))))
B7: 4 | BC7: =IFERROR((COUNTIF(D7:AX7,"A")*4+COUNTIF(D7:AX7,"B")*3+COUNTIF(D7:AX7,"C")*2+COUNTIF(D7:AX7,"D")*1)/(COUNTIF(D7:AX7,"A")+COUNTIF(D7:AX7,"B")+COUNTIF(D7:AX7,"C")+COUNTIF(D7:AX7,"D"))*25,"") | BD7: =IF(BC7="","",IF(BC7>=85,"A",IF(BC7>=70,"B",IF(BC7>=50,"C","D")))) | BG7: =IF(D7="","",IF(D7="A",90,IF(D7="B",75,IF(D7="C",60,45)))) | BH7: =IF(F7="","",IF(F7="A",90,IF(F7="B",75,IF(F7="C",60,45)))) | BI7: =IF(H7="","",IF(H7="A",90,IF(H7="B",75,IF(H7="C",60,45)))) | BJ7: =IF(J7="","",IF(J7="A",90,IF(J7="B",75,IF(J7="C",60,45)))) | BK7: =IF(L7="","",IF(L7="A",90,IF(L7="B",75,IF(L7="C",60,45)))) | BL7: =IF(N7="","",IF(N7="A",90,IF(N7="B",75,IF(N7="C",60,45)))) | BM7: =IF(P7="","",IF(P7="A",90,IF(P7="B",75,IF(P7="C",60,45)))) | BN7: =IF(R7="","",IF(R7="A",90,IF(R7="B",75,IF(R7="C",60,45)))) | BO7: =IF(T7="","",IF(T7="A",90,IF(T7="B",75,IF(T7="C",60,45)))) | BP7: =IF(V7="","",IF(V7="A",90,IF(V7="B",75,IF(V7="C",60,45)))) | BQ7: =IF(X7="","",IF(X7="A",90,IF(X7="B",75,IF(X7="C",60,45)))) | BR7: =IF(Z7="","",IF(Z7="A",90,IF(Z7="B",75,IF(Z7="C",60,45)))) | BS7: =IF(AB7="","",IF(AB7="A",90,IF(AB7="B",75,IF(AB7="C",60,45)))) | BT7: =IF(AD7="","",IF(AD7="A",90,IF(AD7="B",75,IF(AD7="C",60,45)))) | BU7: =IF(AF7="","",IF(AF7="A",90,IF(AF7="B",75,IF(AF7="C",60,45)))) | BV7: =IF(AH7="","",IF(AH7="A",90,IF(AH7="B",75,IF(AH7="C",60,45)))) | BW7: =IF(AJ7="","",IF(AJ7="A",90,IF(AJ7="B",75,IF(AJ7="C",60,45)))) | BX7: =IF(AL7="","",IF(AL7="A",90,IF(AL7="B",75,IF(AL7="C",60,45)))) | BY7: =IF(AN7="","",IF(AN7="A",90,IF(AN7="B",75,IF(AN7="C",60,45)))) | BZ7: =IF(AP7="","",IF(AP7="A",90,IF(AP7="B",75,IF(AP7="C",60,45)))) | CA7: =IF(AR7="","",IF(AR7="A",90,IF(AR7="B",75,IF(AR7="C",60,45)))) | CB7: =IF(AT7="","",IF(AT7="A",90,IF(AT7="B",75,IF(AT7="C",60,45)))) | CC7: =IF(AV7="","",IF(AV7="A",90,IF(AV7="B",75,IF(AV7="C",60,45)))) | CD7: =IF(AX7="","",IF(AX7="A",90,IF(AX7="B",75,IF(AX7="C",60,45))))
BC8: =IFERROR((COUNTIF(D8:AX8,"A")*4+COUNTIF(D8:AX8,"B")*3+COUNTIF(D8:AX8,"C")*2+COUNTIF(D8:AX8,"D")*1)/(COUNTIF(D8:AX8,"A")+COUNTIF(D8:AX8,"B")+COUNTIF(D8:AX8,"C")+COUNTIF(D8:AX8,"D"))*25,"") | BD8: =IF(BC8="","",IF(BC8>=85,"A",IF(BC8>=70,"B",IF(BC8>=50,"C","D")))) | BG8: =IF(D8="","",IF(D8="A",90,IF(D8="B",75,IF(D8="C",60,45)))) | BH8: =IF(F8="","",IF(F8="A",90,IF(F8="B",75,IF(F8="C",60,45)))) | BI8: =IF(H8="","",IF(H8="A",90,IF(H8="B",75,IF(H8="C",60,45)))) | BJ8: =IF(J8="","",IF(J8="A",90,IF(J8="B",75,IF(J8="C",60,45)))) | BK8: =IF(L8="","",IF(L8="A",90,IF(L8="B",75,IF(L8="C",60,45)))) | BL8: =IF(N8="","",IF(N8="A",90,IF(N8="B",75,IF(N8="C",60,45)))) | BM8: =IF(P8="","",IF(P8="A",90,IF(P8="B",75,IF(P8="C",60,45)))) | BN8: =IF(R8="","",IF(R8="A",90,IF(R8="B",75,IF(R8="C",60,45)))) | BO8: =IF(T8="","",IF(T8="A",90,IF(T8="B",75,IF(T8="C",60,45)))) | BP8: =IF(V8="","",IF(V8="A",90,IF(V8="B",75,IF(V8="C",60,45)))) | BQ8: =IF(X8="","",IF(X8="A",90,IF(X8="B",75,IF(X8="C",60,45)))) | BR8: =IF(Z8="","",IF(Z8="A",90,IF(Z8="B",75,IF(Z8="C",60,45)))) | BS8: =IF(AB8="","",IF(AB8="A",90,IF(AB8="B",75,IF(AB8="C",60,45)))) | BT8: =IF(AD8="","",IF(AD8="A",90,IF(AD8="B",75,IF(AD8="C",60,45)))) | BU8: =IF(AF8="","",IF(AF8="A",90,IF(AF8="B",75,IF(AF8="C",60,45)))) | BV8: =IF(AH8="","",IF(AH8="A",90,IF(AH8="B",75,IF(AH8="C",60,45)))) | BW8: =IF(AJ8="","",IF(AJ8="A",90,IF(AJ8="B",75,IF(AJ8="C",60,45)))) | BX8: =IF(AL8="","",IF(AL8="A",90,IF(AL8="B",75,IF(AL8="C",60,45)))) | BY8: =IF(AN8="","",IF(AN8="A",90,IF(AN8="B",75,IF(AN8="C",60,45)))) | BZ8: =IF(AP8="","",IF(AP8="A",90,IF(AP8="B",75,IF(AP8="C",60,45)))) | CA8: =IF(AR8="","",IF(AR8="A",90,IF(AR8="B",75,IF(AR8="C",60,45)))) | CB8: =IF(AT8="","",IF(AT8="A",90,IF(AT8="B",75,IF(AT8="C",60,45)))) | CC8: =IF(AV8="","",IF(AV8="A",90,IF(AV8="B",75,IF(AV8="C",60,45)))) | CD8: =IF(AX8="","",IF(AX8="A",90,IF(AX8="B",75,IF(AX8="C",60,45))))
BC9: =IFERROR((COUNTIF(D9:AX9,"A")*4+COUNTIF(D9:AX9,"B")*3+COUNTIF(D9:AX9,"C")*2+COUNTIF(D9:AX9,"D")*1)/(COUNTIF(D9:AX9,"A")+COUNTIF(D9:AX9,"B")+COUNTIF(D9:AX9,"C")+COUNTIF(D9:AX9,"D"))*25,"") | BD9: =IF(BC9="","",IF(BC9>=85,"A",IF(BC9>=70,"B",IF(BC9>=50,"C","D")))) | BG9: =IF(D9="","",IF(D9="A",90,IF(D9="B",75,IF(D9="C",60,45)))) | BH9: =IF(F9="","",IF(F9="A",90,IF(F9="B",75,IF(F9="C",60,45)))) | BI9: =IF(H9="","",IF(H9="A",90,IF(H9="B",75,IF(H9="C",60,45)))) | BJ9: =IF(J9="","",IF(J9="A",90,IF(J9="B",75,IF(J9="C",60,45)))) | BK9: =IF(L9="","",IF(L9="A",90,IF(L9="B",75,IF(L9="C",60,45)))) | BL9: =IF(N9="","",IF(N9="A",90,IF(N9="B",75,IF(N9="C",60,45)))) | BM9: =IF(P9="","",IF(P9="A",90,IF(P9="B",75,IF(P9="C",60,45)))) | BN9: =IF(R9="","",IF(R9="A",90,IF(R9="B",75,IF(R9="C",60,45)))) | BO9: =IF(T9="","",IF(T9="A",90,IF(T9="B",75,IF(T9="C",60,45)))) | BP9: =IF(V9="","",IF(V9="A",90,IF(V9="B",75,IF(V9="C",60,45)))) | BQ9: =IF(X9="","",IF(X9="A",90,IF(X9="B",75,IF(X9="C",60,45)))) | BR9: =IF(Z9="","",IF(Z9="A",90,IF(Z9="B",75,IF(Z9="C",60,45)))) | BS9: =IF(AB9="","",IF(AB9="A",90,IF(AB9="B",75,IF(AB9="C",60,45)))) | BT9: =IF(AD9="","",IF(AD9="A",90,IF(AD9="B",75,IF(AD9="C",60,45)))) | BU9: =IF(AF9="","",IF(AF9="A",90,IF(AF9="B",75,IF(AF9="C",60,45)))) | BV9: =IF(AH9="","",IF(AH9="A",90,IF(AH9="B",75,IF(AH9="C",60,45)))) | BW9: =IF(AJ9="","",IF(AJ9="A",90,IF(AJ9="B",75,IF(AJ9="C",60,45)))) | BX9: =IF(AL9="","",IF(AL9="A",90,IF(AL9="B",75,IF(AL9="C",60,45)))) | BY9: =IF(AN9="","",IF(AN9="A",90,IF(AN9="B",75,IF(AN9="C",60,45)))) | BZ9: =IF(AP9="","",IF(AP9="A",90,IF(AP9="B",75,IF(AP9="C",60,45)))) | CA9: =IF(AR9="","",IF(AR9="A",90,IF(AR9="B",75,IF(AR9="C",60,45)))) | CB9: =IF(AT9="","",IF(AT9="A",90,IF(AT9="B",75,IF(AT9="C",60,45)))) | CC9: =IF(AV9="","",IF(AV9="A",90,IF(AV9="B",75,IF(AV9="C",60,45)))) | CD9: =IF(AX9="","",IF(AX9="A",90,IF(AX9="B",75,IF(AX9="C",60,45))))
BC10: =IFERROR((COUNTIF(D10:AX10,"A")*4+COUNTIF(D10:AX10,"B")*3+COUNTIF(D10:AX10,"C")*2+COUNTIF(D10:AX10,"D")*1)/(COUNTIF(D10:AX10,"A")+COUNTIF(D10:AX10,"B")+COUNTIF(D10:AX10,"C")+COUNTIF(D10:AX10,"D"))*25,"") | BD10: =IF(BC10="","",IF(BC10>=85,"A",IF(BC10>=70,"B",IF(BC10>=50,"C","D")))) | BG10: =IF(D10="","",IF(D10="A",90,IF(D10="B",75,IF(D10="C",60,45)))) | BH10: =IF(F10="","",IF(F10="A",90,IF(F10="B",75,IF(F10="C",60,45)))) | BI10: =IF(H10="","",IF(H10="A",90,IF(H10="B",75,IF(H10="C",60,45)))) | BJ10: =IF(J10="","",IF(J10="A",90,IF(J10="B",75,IF(J10="C",60,45)))) | BK10: =IF(L10="","",IF(L10="A",90,IF(L10="B",75,IF(L10="C",60,45)))) | BL10: =IF(N10="","",IF(N10="A",90,IF(N10="B",75,IF(N10="C",60,45)))) | BM10: =IF(P10="","",IF(P10="A",90,IF(P10="B",75,IF(P10="C",60,45)))) | BN10: =IF(R10="","",IF(R10="A",90,IF(R10="B",75,IF(R10="C",60,45)))) | BO10: =IF(T10="","",IF(T10="A",90,IF(T10="B",75,IF(T10="C",60,45)))) | BP10: =IF(V10="","",IF(V10="A",90,IF(V10="B",75,IF(V10="C",60,45)))) | BQ10: =IF(X10="","",IF(X10="A",90,IF(X10="B",75,IF(X10="C",60,45)))) | BR10: =IF(Z10="","",IF(Z10="A",90,IF(Z10="B",75,IF(Z10="C",60,45)))) | BS10: =IF(AB10="","",IF(AB10="A",90,IF(AB10="B",75,IF(AB10="C",60,45)))) | BT10: =IF(AD10="","",IF(AD10="A",90,IF(AD10="B",75,IF(AD10="C",60,45)))) | BU10: =IF(AF10="","",IF(AF10="A",90,IF(AF10="B",75,IF(AF10="C",60,45)))) | BV10: =IF(AH10="","",IF(AH10="A",90,IF(AH10="B",75,IF(AH10="C",60,45)))) | BW10: =IF(AJ10="","",IF(AJ10="A",90,IF(AJ10="B",75,IF(AJ10="C",60,45)))) | BX10: =IF(AL10="","",IF(AL10="A",90,IF(AL10="B",75,IF(AL10="C",60,45)))) | BY10: =IF(AN10="","",IF(AN10="A",90,IF(AN10="B",75,IF(AN10="C",60,45)))) | BZ10: =IF(AP10="","",IF(AP10="A",90,IF(AP10="B",75,IF(AP10="C",60,45)))) | CA10: =IF(AR10="","",IF(AR10="A",90,IF(AR10="B",75,IF(AR10="C",60,45)))) | CB10: =IF(AT10="","",IF(AT10="A",90,IF(AT10="B",75,IF(AT10="C",60,45)))) | CC10: =IF(AV10="","",IF(AV10="A",90,IF(AV10="B",75,IF(AV10="C",60,45)))) | CD10: =IF(AX10="","",IF(AX10="A",90,IF(AX10="B",75,IF(AX10="C",60,45))))
BC11: =IFERROR((COUNTIF(D11:AX11,"A")*4+COUNTIF(D11:AX11,"B")*3+COUNTIF(D11:AX11,"C")*2+COUNTIF(D11:AX11,"D")*1)/(COUNTIF(D11:AX11,"A")+COUNTIF(D11:AX11,"B")+COUNTIF(D11:AX11,"C")+COUNTIF(D11:AX11,"D"))*25,"") | BD11: =IF(BC11="","",IF(BC11>=85,"A",IF(BC11>=70,"B",IF(BC11>=50,"C","D")))) | BG11: =IF(D11="","",IF(D11="A",90,IF(D11="B",75,IF(D11="C",60,45)))) | BH11: =IF(F11="","",IF(F11="A",90,IF(F11="B",75,IF(F11="C",60,45)))) | BI11: =IF(H11="","",IF(H11="A",90,IF(H11="B",75,IF(H11="C",60,45)))) | BJ11: =IF(J11="","",IF(J11="A",90,IF(J11="B",75,IF(J11="C",60,45)))) | BK11: =IF(L11="","",IF(L11="A",90,IF(L11="B",75,IF(L11="C",60,45)))) | BL11: =IF(N11="","",IF(N11="A",90,IF(N11="B",75,IF(N11="C",60,45)))) | BM11: =IF(P11="","",IF(P11="A",90,IF(P11="B",75,IF(P11="C",60,45)))) | BN11: =IF(R11="","",IF(R11="A",90,IF(R11="B",75,IF(R11="C",60,45)))) | BO11: =IF(T11="","",IF(T11="A",90,IF(T11="B",75,IF(T11="C",60,45)))) | BP11: =IF(V11="","",IF(V11="A",90,IF(V11="B",75,IF(V11="C",60,45)))) | BQ11: =IF(X11="","",IF(X11="A",90,IF(X11="B",75,IF(X11="C",60,45)))) | BR11: =IF(Z11="","",IF(Z11="A",90,IF(Z11="B",75,IF(Z11="C",60,45)))) | BS11: =IF(AB11="","",IF(AB11="A",90,IF(AB11="B",75,IF(AB11="C",60,45)))) | BT11: =IF(AD11="","",IF(AD11="A",90,IF(AD11="B",75,IF(AD11="C",60,45)))) | BU11: =IF(AF11="","",IF(AF11="A",90,IF(AF11="B",75,IF(AF11="C",60,45)))) | BV11: =IF(AH11="","",IF(AH11="A",90,IF(AH11="B",75,IF(AH11="C",60,45)))) | BW11: =IF(AJ11="","",IF(AJ11="A",90,IF(AJ11="B",75,IF(AJ11="C",60,45)))) | BX11: =IF(AL11="","",IF(AL11="A",90,IF(AL11="B",75,IF(AL11="C",60,45)))) | BY11: =IF(AN11="","",IF(AN11="A",90,IF(AN11="B",75,IF(AN11="C",60,45)))) | BZ11: =IF(AP11="","",IF(AP11="A",90,IF(AP11="B",75,IF(AP11="C",60,45)))) | CA11: =IF(AR11="","",IF(AR11="A",90,IF(AR11="B",75,IF(AR11="C",60,45)))) | CB11: =IF(AT11="","",IF(AT11="A",90,IF(AT11="B",75,IF(AT11="C",60,45)))) | CC11: =IF(AV11="","",IF(AV11="A",90,IF(AV11="B",75,IF(AV11="C",60,45)))) | CD11: =IF(AX11="","",IF(AX11="A",90,IF(AX11="B",75,IF(AX11="C",60,45))))
BC12: =IFERROR((COUNTIF(D12:AX12,"A")*4+COUNTIF(D12:AX12,"B")*3+COUNTIF(D12:AX12,"C")*2+COUNTIF(D12:AX12,"D")*1)/(COUNTIF(D12:AX12,"A")+COUNTIF(D12:AX12,"B")+COUNTIF(D12:AX12,"C")+COUNTIF(D12:AX12,"D"))*25,"") | BD12: =IF(BC12="","",IF(BC12>=85,"A",IF(BC12>=70,"B",IF(BC12>=50,"C","D")))) | BG12: =IF(D12="","",IF(D12="A",90,IF(D12="B",75,IF(D12="C",60,45)))) | BH12: =IF(F12="","",IF(F12="A",90,IF(F12="B",75,IF(F12="C",60,45)))) | BI12: =IF(H12="","",IF(H12="A",90,IF(H12="B",75,IF(H12="C",60,45)))) | BJ12: =IF(J12="","",IF(J12="A",90,IF(J12="B",75,IF(J12="C",60,45)))) | BK12: =IF(L12="","",IF(L12="A",90,IF(L12="B",75,IF(L12="C",60,45)))) | BL12: =IF(N12="","",IF(N12="A",90,IF(N12="B",75,IF(N12="C",60,45)))) | BM12: =IF(P12="","",IF(P12="A",90,IF(P12="B",75,IF(P12="C",60,45)))) | BN12: =IF(R12="","",IF(R12="A",90,IF(R12="B",75,IF(R12="C",60,45)))) | BO12: =IF(T12="","",IF(T12="A",90,IF(T12="B",75,IF(T12="C",60,45)))) | BP12: =IF(V12="","",IF(V12="A",90,IF(V12="B",75,IF(V12="C",60,45)))) | BQ12: =IF(X12="","",IF(X12="A",90,IF(X12="B",75,IF(X12="C",60,45)))) | BR12: =IF(Z12="","",IF(Z12="A",90,IF(Z12="B",75,IF(Z12="C",60,45)))) | BS12: =IF(AB12="","",IF(AB12="A",90,IF(AB12="B",75,IF(AB12="C",60,45)))) | BT12: =IF(AD12="","",IF(AD12="A",90,IF(AD12="B",75,IF(AD12="C",60,45)))) | BU12: =IF(AF12="","",IF(AF12="A",90,IF(AF12="B",75,IF(AF12="C",60,45)))) | BV12: =IF(AH12="","",IF(AH12="A",90,IF(AH12="B",75,IF(AH12="C",60,45)))) | BW12: =IF(AJ12="","",IF(AJ12="A",90,IF(AJ12="B",75,IF(AJ12="C",60,45)))) | BX12: =IF(AL12="","",IF(AL12="A",90,IF(AL12="B",75,IF(AL12="C",60,45)))) | BY12: =IF(AN12="","",IF(AN12="A",90,IF(AN12="B",75,IF(AN12="C",60,45)))) | BZ12: =IF(AP12="","",IF(AP12="A",90,IF(AP12="B",75,IF(AP12="C",60,45)))) | CA12: =IF(AR12="","",IF(AR12="A",90,IF(AR12="B",75,IF(AR12="C",60,45)))) | CB12: =IF(AT12="","",IF(AT12="A",90,IF(AT12="B",75,IF(AT12="C",60,45)))) | CC12: =IF(AV12="","",IF(AV12="A",90,IF(AV12="B",75,IF(AV12="C",60,45)))) | CD12: =IF(AX12="","",IF(AX12="A",90,IF(AX12="B",75,IF(AX12="C",60,45))))
BC13: =IFERROR((COUNTIF(D13:AX13,"A")*4+COUNTIF(D13:AX13,"B")*3+COUNTIF(D13:AX13,"C")*2+COUNTIF(D13:AX13,"D")*1)/(COUNTIF(D13:AX13,"A")+COUNTIF(D13:AX13,"B")+COUNTIF(D13:AX13,"C")+COUNTIF(D13:AX13,"D"))*25,"") | BD13: =IF(BC13="","",IF(BC13>=85,"A",IF(BC13>=70,"B",IF(BC13>=50,"C","D")))) | BG13: =IF(D13="","",IF(D13="A",90,IF(D13="B",75,IF(D13="C",60,45)))) | BH13: =IF(F13="","",IF(F13="A",90,IF(F13="B",75,IF(F13="C",60,45)))) | BI13: =IF(H13="","",IF(H13="A",90,IF(H13="B",75,IF(H13="C",60,45)))) | BJ13: =IF(J13="","",IF(J13="A",90,IF(J13="B",75,IF(J13="C",60,45)))) | BK13: =IF(L13="","",IF(L13="A",90,IF(L13="B",75,IF(L13="C",60,45)))) | BL13: =IF(N13="","",IF(N13="A",90,IF(N13="B",75,IF(N13="C",60,45)))) | BM13: =IF(P13="","",IF(P13="A",90,IF(P13="B",75,IF(P13="C",60,45)))) | BN13: =IF(R13="","",IF(R13="A",90,IF(R13="B",75,IF(R13="C",60,45)))) | BO13: =IF(T13="","",IF(T13="A",90,IF(T13="B",75,IF(T13="C",60,45)))) | BP13: =IF(V13="","",IF(V13="A",90,IF(V13="B",75,IF(V13="C",60,45)))) | BQ13: =IF(X13="","",IF(X13="A",90,IF(X13="B",75,IF(X13="C",60,45)))) | BR13: =IF(Z13="","",IF(Z13="A",90,IF(Z13="B",75,IF(Z13="C",60,45)))) | BS13: =IF(AB13="","",IF(AB13="A",90,IF(AB13="B",75,IF(AB13="C",60,45)))) | BT13: =IF(AD13="","",IF(AD13="A",90,IF(AD13="B",75,IF(AD13="C",60,45)))) | BU13: =IF(AF13="","",IF(AF13="A",90,IF(AF13="B",75,IF(AF13="C",60,45)))) | BV13: =IF(AH13="","",IF(AH13="A",90,IF(AH13="B",75,IF(AH13="C",60,45)))) | BW13: =IF(AJ13="","",IF(AJ13="A",90,IF(AJ13="B",75,IF(AJ13="C",60,45)))) | BX13: =IF(AL13="","",IF(AL13="A",90,IF(AL13="B",75,IF(AL13="C",60,45)))) | BY13: =IF(AN13="","",IF(AN13="A",90,IF(AN13="B",75,IF(AN13="C",60,45)))) | BZ13: =IF(AP13="","",IF(AP13="A",90,IF(AP13="B",75,IF(AP13="C",60,45)))) | CA13: =IF(AR13="","",IF(AR13="A",90,IF(AR13="B",75,IF(AR13="C",60,45)))) | CB13: =IF(AT13="","",IF(AT13="A",90,IF(AT13="B",75,IF(AT13="C",60,45)))) | CC13: =IF(AV13="","",IF(AV13="A",90,IF(AV13="B",75,IF(AV13="C",60,45)))) | CD13: =IF(AX13="","",IF(AX13="A",90,IF(AX13="B",75,IF(AX13="C",60,45))))
BC14: =IFERROR((COUNTIF(D14:AX14,"A")*4+COUNTIF(D14:AX14,"B")*3+COUNTIF(D14:AX14,"C")*2+COUNTIF(D14:AX14,"D")*1)/(COUNTIF(D14:AX14,"A")+COUNTIF(D14:AX14,"B")+COUNTIF(D14:AX14,"C")+COUNTIF(D14:AX14,"D"))*25,"") | BD14: =IF(BC14="","",IF(BC14>=85,"A",IF(BC14>=70,"B",IF(BC14>=50,"C","D")))) | BG14: =IF(D14="","",IF(D14="A",90,IF(D14="B",75,IF(D14="C",60,45)))) | BH14: =IF(F14="","",IF(F14="A",90,IF(F14="B",75,IF(F14="C",60,45)))) | BI14: =IF(H14="","",IF(H14="A",90,IF(H14="B",75,IF(H14="C",60,45)))) | BJ14: =IF(J14="","",IF(J14="A",90,IF(J14="B",75,IF(J14="C",60,45)))) | BK14: =IF(L14="","",IF(L14="A",90,IF(L14="B",75,IF(L14="C",60,45)))) | BL14: =IF(N14="","",IF(N14="A",90,IF(N14="B",75,IF(N14="C",60,45)))) | BM14: =IF(P14="","",IF(P14="A",90,IF(P14="B",75,IF(P14="C",60,45)))) | BN14: =IF(R14="","",IF(R14="A",90,IF(R14="B",75,IF(R14="C",60,45)))) | BO14: =IF(T14="","",IF(T14="A",90,IF(T14="B",75,IF(T14="C",60,45)))) | BP14: =IF(V14="","",IF(V14="A",90,IF(V14="B",75,IF(V14="C",60,45)))) | BQ14: =IF(X14="","",IF(X14="A",90,IF(X14="B",75,IF(X14="C",60,45)))) | BR14: =IF(Z14="","",IF(Z14="A",90,IF(Z14="B",75,IF(Z14="C",60,45)))) | BS14: =IF(AB14="","",IF(AB14="A",90,IF(AB14="B",75,IF(AB14="C",60,45)))) | BT14: =IF(AD14="","",IF(AD14="A",90,IF(AD14="B",75,IF(AD14="C",60,45)))) | BU14: =IF(AF14="","",IF(AF14="A",90,IF(AF14="B",75,IF(AF14="C",60,45)))) | BV14: =IF(AH14="","",IF(AH14="A",90,IF(AH14="B",75,IF(AH14="C",60,45)))) | BW14: =IF(AJ14="","",IF(AJ14="A",90,IF(AJ14="B",75,IF(AJ14="C",60,45)))) | BX14: =IF(AL14="","",IF(AL14="A",90,IF(AL14="B",75,IF(AL14="C",60,45)))) | BY14: =IF(AN14="","",IF(AN14="A",90,IF(AN14="B",75,IF(AN14="C",60,45)))) | BZ14: =IF(AP14="","",IF(AP14="A",90,IF(AP14="B",75,IF(AP14="C",60,45)))) | CA14: =IF(AR14="","",IF(AR14="A",90,IF(AR14="B",75,IF(AR14="C",60,45)))) | CB14: =IF(AT14="","",IF(AT14="A",90,IF(AT14="B",75,IF(AT14="C",60,45)))) | CC14: =IF(AV14="","",IF(AV14="A",90,IF(AV14="B",75,IF(AV14="C",60,45)))) | CD14: =IF(AX14="","",IF(AX14="A",90,IF(AX14="B",75,IF(AX14="C",60,45))))
BC15: =IFERROR((COUNTIF(D15:AX15,"A")*4+COUNTIF(D15:AX15,"B")*3+COUNTIF(D15:AX15,"C")*2+COUNTIF(D15:AX15,"D")*1)/(COUNTIF(D15:AX15,"A")+COUNTIF(D15:AX15,"B")+COUNTIF(D15:AX15,"C")+COUNTIF(D15:AX15,"D"))*25,"") | BD15: =IF(BC15="","",IF(BC15>=85,"A",IF(BC15>=70,"B",IF(BC15>=50,"C","D")))) | BG15: =IF(D15="","",IF(D15="A",90,IF(D15="B",75,IF(D15="C",60,45)))) | BH15: =IF(F15="","",IF(F15="A",90,IF(F15="B",75,IF(F15="C",60,45)))) | BI15: =IF(H15="","",IF(H15="A",90,IF(H15="B",75,IF(H15="C",60,45)))) | BJ15: =IF(J15="","",IF(J15="A",90,IF(J15="B",75,IF(J15="C",60,45)))) | BK15: =IF(L15="","",IF(L15="A",90,IF(L15="B",75,IF(L15="C",60,45)))) | BL15: =IF(N15="","",IF(N15="A",90,IF(N15="B",75,IF(N15="C",60,45)))) | BM15: =IF(P15="","",IF(P15="A",90,IF(P15="B",75,IF(P15="C",60,45)))) | BN15: =IF(R15="","",IF(R15="A",90,IF(R15="B",75,IF(R15="C",60,45)))) | BO15: =IF(T15="","",IF(T15="A",90,IF(T15="B",75,IF(T15="C",60,45)))) | BP15: =IF(V15="","",IF(V15="A",90,IF(V15="B",75,IF(V15="C",60,45)))) | BQ15: =IF(X15="","",IF(X15="A",90,IF(X15="B",75,IF(X15="C",60,45)))) | BR15: =IF(Z15="","",IF(Z15="A",90,IF(Z15="B",75,IF(Z15="C",60,45)))) | BS15: =IF(AB15="","",IF(AB15="A",90,IF(AB15="B",75,IF(AB15="C",60,45)))) | BT15: =IF(AD15="","",IF(AD15="A",90,IF(AD15="B",75,IF(AD15="C",60,45)))) | BU15: =IF(AF15="","",IF(AF15="A",90,IF(AF15="B",75,IF(AF15="C",60,45)))) | BV15: =IF(AH15="","",IF(AH15="A",90,IF(AH15="B",75,IF(AH15="C",60,45)))) | BW15: =IF(AJ15="","",IF(AJ15="A",90,IF(AJ15="B",75,IF(AJ15="C",60,45)))) | BX15: =IF(AL15="","",IF(AL15="A",90,IF(AL15="B",75,IF(AL15="C",60,45)))) | BY15: =IF(AN15="","",IF(AN15="A",90,IF(AN15="B",75,IF(AN15="C",60,45)))) | BZ15: =IF(AP15="","",IF(AP15="A",90,IF(AP15="B",75,IF(AP15="C",60,45)))) | CA15: =IF(AR15="","",IF(AR15="A",90,IF(AR15="B",75,IF(AR15="C",60,45)))) | CB15: =IF(AT15="","",IF(AT15="A",90,IF(AT15="B",75,IF(AT15="C",60,45)))) | CC15: =IF(AV15="","",IF(AV15="A",90,IF(AV15="B",75,IF(AV15="C",60,45)))) | CD15: =IF(AX15="","",IF(AX15="A",90,IF(AX15="B",75,IF(AX15="C",60,45))))
BC16: =IFERROR((COUNTIF(D16:AX16,"A")*4+COUNTIF(D16:AX16,"B")*3+COUNTIF(D16:AX16,"C")*2+COUNTIF(D16:AX16,"D")*1)/(COUNTIF(D16:AX16,"A")+COUNTIF(D16:AX16,"B")+COUNTIF(D16:AX16,"C")+COUNTIF(D16:AX16,"D"))*25,"") | BD16: =IF(BC16="","",IF(BC16>=85,"A",IF(BC16>=70,"B",IF(BC16>=50,"C","D")))) | BG16: =IF(D16="","",IF(D16="A",90,IF(D16="B",75,IF(D16="C",60,45)))) | BH16: =IF(F16="","",IF(F16="A",90,IF(F16="B",75,IF(F16="C",60,45)))) | BI16: =IF(H16="","",IF(H16="A",90,IF(H16="B",75,IF(H16="C",60,45)))) | BJ16: =IF(J16="","",IF(J16="A",90,IF(J16="B",75,IF(J16="C",60,45)))) | BK16: =IF(L16="","",IF(L16="A",90,IF(L16="B",75,IF(L16="C",60,45)))) | BL16: =IF(N16="","",IF(N16="A",90,IF(N16="B",75,IF(N16="C",60,45)))) | BM16: =IF(P16="","",IF(P16="A",90,IF(P16="B",75,IF(P16="C",60,45)))) | BN16: =IF(R16="","",IF(R16="A",90,IF(R16="B",75,IF(R16="C",60,45)))) | BO16: =IF(T16="","",IF(T16="A",90,IF(T16="B",75,IF(T16="C",60,45)))) | BP16: =IF(V16="","",IF(V16="A",90,IF(V16="B",75,IF(V16="C",60,45)))) | BQ16: =IF(X16="","",IF(X16="A",90,IF(X16="B",75,IF(X16="C",60,45)))) | BR16: =IF(Z16="","",IF(Z16="A",90,IF(Z16="B",75,IF(Z16="C",60,45)))) | BS16: =IF(AB16="","",IF(AB16="A",90,IF(AB16="B",75,IF(AB16="C",60,45)))) | BT16: =IF(AD16="","",IF(AD16="A",90,IF(AD16="B",75,IF(AD16="C",60,45)))) | BU16: =IF(AF16="","",IF(AF16="A",90,IF(AF16="B",75,IF(AF16="C",60,45)))) | BV16: =IF(AH16="","",IF(AH16="A",90,IF(AH16="B",75,IF(AH16="C",60,45)))) | BW16: =IF(AJ16="","",IF(AJ16="A",90,IF(AJ16="B",75,IF(AJ16="C",60,45)))) | BX16: =IF(AL16="","",IF(AL16="A",90,IF(AL16="B",75,IF(AL16="C",60,45)))) | BY16: =IF(AN16="","",IF(AN16="A",90,IF(AN16="B",75,IF(AN16="C",60,45)))) | BZ16: =IF(AP16="","",IF(AP16="A",90,IF(AP16="B",75,IF(AP16="C",60,45)))) | CA16: =IF(AR16="","",IF(AR16="A",90,IF(AR16="B",75,IF(AR16="C",60,45)))) | CB16: =IF(AT16="","",IF(AT16="A",90,IF(AT16="B",75,IF(AT16="C",60,45)))) | CC16: =IF(AV16="","",IF(AV16="A",90,IF(AV16="B",75,IF(AV16="C",60,45)))) | CD16: =IF(AX16="","",IF(AX16="A",90,IF(AX16="B",75,IF(AX16="C",60,45))))
BC17: =IFERROR((COUNTIF(D17:AX17,"A")*4+COUNTIF(D17:AX17,"B")*3+COUNTIF(D17:AX17,"C")*2+COUNTIF(D17:AX17,"D")*1)/(COUNTIF(D17:AX17,"A")+COUNTIF(D17:AX17,"B")+COUNTIF(D17:AX17,"C")+COUNTIF(D17:AX17,"D"))*25,"") | BD17: =IF(BC17="","",IF(BC17>=85,"A",IF(BC17>=70,"B",IF(BC17>=50,"C","D")))) | BG17: =IF(D17="","",IF(D17="A",90,IF(D17="B",75,IF(D17="C",60,45)))) | BH17: =IF(F17="","",IF(F17="A",90,IF(F17="B",75,IF(F17="C",60,45)))) | BI17: =IF(H17="","",IF(H17="A",90,IF(H17="B",75,IF(H17="C",60,45)))) | BJ17: =IF(J17="","",IF(J17="A",90,IF(J17="B",75,IF(J17="C",60,45)))) | BK17: =IF(L17="","",IF(L17="A",90,IF(L17="B",75,IF(L17="C",60,45)))) | BL17: =IF(N17="","",IF(N17="A",90,IF(N17="B",75,IF(N17="C",60,45)))) | BM17: =IF(P17="","",IF(P17="A",90,IF(P17="B",75,IF(P17="C",60,45)))) | BN17: =IF(R17="","",IF(R17="A",90,IF(R17="B",75,IF(R17="C",60,45)))) | BO17: =IF(T17="","",IF(T17="A",90,IF(T17="B",75,IF(T17="C",60,45)))) | BP17: =IF(V17="","",IF(V17="A",90,IF(V17="B",75,IF(V17="C",60,45)))) | BQ17: =IF(X17="","",IF(X17="A",90,IF(X17="B",75,IF(X17="C",60,45)))) | BR17: =IF(Z17="","",IF(Z17="A",90,IF(Z17="B",75,IF(Z17="C",60,45)))) | BS17: =IF(AB17="","",IF(AB17="A",90,IF(AB17="B",75,IF(AB17="C",60,45)))) | BT17: =IF(AD17="","",IF(AD17="A",90,IF(AD17="B",75,IF(AD17="C",60,45)))) | BU17: =IF(AF17="","",IF(AF17="A",90,IF(AF17="B",75,IF(AF17="C",60,45)))) | BV17: =IF(AH17="","",IF(AH17="A",90,IF(AH17="B",75,IF(AH17="C",60,45)))) | BW17: =IF(AJ17="","",IF(AJ17="A",90,IF(AJ17="B",75,IF(AJ17="C",60,45)))) | BX17: =IF(AL17="","",IF(AL17="A",90,IF(AL17="B",75,IF(AL17="C",60,45)))) | BY17: =IF(AN17="","",IF(AN17="A",90,IF(AN17="B",75,IF(AN17="C",60,45)))) | BZ17: =IF(AP17="","",IF(AP17="A",90,IF(AP17="B",75,IF(AP17="C",60,45)))) | CA17: =IF(AR17="","",IF(AR17="A",90,IF(AR17="B",75,IF(AR17="C",60,45)))) | CB17: =IF(AT17="","",IF(AT17="A",90,IF(AT17="B",75,IF(AT17="C",60,45)))) | CC17: =IF(AV17="","",IF(AV17="A",90,IF(AV17="B",75,IF(AV17="C",60,45)))) | CD17: =IF(AX17="","",IF(AX17="A",90,IF(AX17="B",75,IF(AX17="C",60,45))))
BC18: =IFERROR((COUNTIF(D18:AX18,"A")*4+COUNTIF(D18:AX18,"B")*3+COUNTIF(D18:AX18,"C")*2+COUNTIF(D18:AX18,"D")*1)/(COUNTIF(D18:AX18,"A")+COUNTIF(D18:AX18,"B")+COUNTIF(D18:AX18,"C")+COUNTIF(D18:AX18,"D"))*25,"") | BD18: =IF(BC18="","",IF(BC18>=85,"A",IF(BC18>=70,"B",IF(BC18>=50,"C","D")))) | BG18: =IF(D18="","",IF(D18="A",90,IF(D18="B",75,IF(D18="C",60,45)))) | BH18: =IF(F18="","",IF(F18="A",90,IF(F18="B",75,IF(F18="C",60,45)))) | BI18: =IF(H18="","",IF(H18="A",90,IF(H18="B",75,IF(H18="C",60,45)))) | BJ18: =IF(J18="","",IF(J18="A",90,IF(J18="B",75,IF(J18="C",60,45)))) | BK18: =IF(L18="","",IF(L18="A",90,IF(L18="B",75,IF(L18="C",60,45)))) | BL18: =IF(N18="","",IF(N18="A",90,IF(N18="B",75,IF(N18="C",60,45)))) | BM18: =IF(P18="","",IF(P18="A",90,IF(P18="B",75,IF(P18="C",60,45)))) | BN18: =IF(R18="","",IF(R18="A",90,IF(R18="B",75,IF(R18="C",60,45)))) | BO18: =IF(T18="","",IF(T18="A",90,IF(T18="B",75,IF(T18="C",60,45)))) | BP18: =IF(V18="","",IF(V18="A",90,IF(V18="B",75,IF(V18="C",60,45)))) | BQ18: =IF(X18="","",IF(X18="A",90,IF(X18="B",75,IF(X18="C",60,45)))) | BR18: =IF(Z18="","",IF(Z18="A",90,IF(Z18="B",75,IF(Z18="C",60,45)))) | BS18: =IF(AB18="","",IF(AB18="A",90,IF(AB18="B",75,IF(AB18="C",60,45)))) | BT18: =IF(AD18="","",IF(AD18="A",90,IF(AD18="B",75,IF(AD18="C",60,45)))) | BU18: =IF(AF18="","",IF(AF18="A",90,IF(AF18="B",75,IF(AF18="C",60,45)))) | BV18: =IF(AH18="","",IF(AH18="A",90,IF(AH18="B",75,IF(AH18="C",60,45)))) | BW18: =IF(AJ18="","",IF(AJ18="A",90,IF(AJ18="B",75,IF(AJ18="C",60,45)))) | BX18: =IF(AL18="","",IF(AL18="A",90,IF(AL18="B",75,IF(AL18="C",60,45)))) | BY18: =IF(AN18="","",IF(AN18="A",90,IF(AN18="B",75,IF(AN18="C",60,45)))) | BZ18: =IF(AP18="","",IF(AP18="A",90,IF(AP18="B",75,IF(AP18="C",60,45)))) | CA18: =IF(AR18="","",IF(AR18="A",90,IF(AR18="B",75,IF(AR18="C",60,45)))) | CB18: =IF(AT18="","",IF(AT18="A",90,IF(AT18="B",75,IF(AT18="C",60,45)))) | CC18: =IF(AV18="","",IF(AV18="A",90,IF(AV18="B",75,IF(AV18="C",60,45)))) | CD18: =IF(AX18="","",IF(AX18="A",90,IF(AX18="B",75,IF(AX18="C",60,45))))
BC19: =IFERROR((COUNTIF(D19:AX19,"A")*4+COUNTIF(D19:AX19,"B")*3+COUNTIF(D19:AX19,"C")*2+COUNTIF(D19:AX19,"D")*1)/(COUNTIF(D19:AX19,"A")+COUNTIF(D19:AX19,"B")+COUNTIF(D19:AX19,"C")+COUNTIF(D19:AX19,"D"))*25,"") | BD19: =IF(BC19="","",IF(BC19>=85,"A",IF(BC19>=70,"B",IF(BC19>=50,"C","D")))) | BG19: =IF(D19="","",IF(D19="A",90,IF(D19="B",75,IF(D19="C",60,45)))) | BH19: =IF(F19="","",IF(F19="A",90,IF(F19="B",75,IF(F19="C",60,45)))) | BI19: =IF(H19="","",IF(H19="A",90,IF(H19="B",75,IF(H19="C",60,45)))) | BJ19: =IF(J19="","",IF(J19="A",90,IF(J19="B",75,IF(J19="C",60,45)))) | BK19: =IF(L19="","",IF(L19="A",90,IF(L19="B",75,IF(L19="C",60,45)))) | BL19: =IF(N19="","",IF(N19="A",90,IF(N19="B",75,IF(N19="C",60,45)))) | BM19: =IF(P19="","",IF(P19="A",90,IF(P19="B",75,IF(P19="C",60,45)))) | BN19: =IF(R19="","",IF(R19="A",90,IF(R19="B",75,IF(R19="C",60,45)))) | BO19: =IF(T19="","",IF(T19="A",90,IF(T19="B",75,IF(T19="C",60,45)))) | BP19: =IF(V19="","",IF(V19="A",90,IF(V19="B",75,IF(V19="C",60,45)))) | BQ19: =IF(X19="","",IF(X19="A",90,IF(X19="B",75,IF(X19="C",60,45)))) | BR19: =IF(Z19="","",IF(Z19="A",90,IF(Z19="B",75,IF(Z19="C",60,45)))) | BS19: =IF(AB19="","",IF(AB19="A",90,IF(AB19="B",75,IF(AB19="C",60,45)))) | BT19: =IF(AD19="","",IF(AD19="A",90,IF(AD19="B",75,IF(AD19="C",60,45)))) | BU19: =IF(AF19="","",IF(AF19="A",90,IF(AF19="B",75,IF(AF19="C",60,45)))) | BV19: =IF(AH19="","",IF(AH19="A",90,IF(AH19="B",75,IF(AH19="C",60,45)))) | BW19: =IF(AJ19="","",IF(AJ19="A",90,IF(AJ19="B",75,IF(AJ19="C",60,45)))) | BX19: =IF(AL19="","",IF(AL19="A",90,IF(AL19="B",75,IF(AL19="C",60,45)))) | BY19: =IF(AN19="","",IF(AN19="A",90,IF(AN19="B",75,IF(AN19="C",60,45)))) | BZ19: =IF(AP19="","",IF(AP19="A",90,IF(AP19="B",75,IF(AP19="C",60,45)))) | CA19: =IF(AR19="","",IF(AR19="A",90,IF(AR19="B",75,IF(AR19="C",60,45)))) | CB19: =IF(AT19="","",IF(AT19="A",90,IF(AT19="B",75,IF(AT19="C",60,45)))) | CC19: =IF(AV19="","",IF(AV19="A",90,IF(AV19="B",75,IF(AV19="C",60,45)))) | CD19: =IF(AX19="","",IF(AX19="A",90,IF(AX19="B",75,IF(AX19="C",60,45))))
... BC200: =IFERROR((COUNTIF(D200:AX200,"A")*4+COUNTIF(D200:AX200,"B")*3+COUNTIF(D200:AX200,"C")*2+COUNTIF(D200:AX200,"D")*1)/(COUNTIF(D200:AX200,"A")+COUNTIF(D200:AX200,"B")+COUNTIF(D200:AX200,"C")+COUNTIF(D200:AX200,"D"))*25,"") | BD200: =IF(BC200="","",IF(BC200>=85,"A",IF(BC200>=70,"B",IF(BC200>=50,"C","D")))) | BG200: =IF(D200="","",IF(D200="A",90,IF(D200="B",75,IF(D200="C",60,45)))) | BH200: =IF(F200="","",IF(F200="A",90,IF(F200="B",75,IF(F200="C",60,45)))) | BI200: =IF(H200="","",IF(H200="A",90,IF(H200="B",75,IF(H200="C",60,45)))) | BJ200: =IF(J200="","",IF(J200="A",90,IF(J200="B",75,IF(J200="C",60,45)))) | BK200: =IF(L200="","",IF(L200="A",90,IF(L200="B",75,IF(L200="C",60,45)))) | BL200: =IF(N200="","",IF(N200="A",90,IF(N200="B",75,IF(N200="C",60,45)))) | BM200: =IF(P200="","",IF(P200="A",90,IF(P200="B",75,IF(P200="C",60,45)))) | BN200: =IF(R200="","",IF(R200="A",90,IF(R200="B",75,IF(R200="C",60,45)))) | BO200: =IF(T200="","",IF(T200="A",90,IF(T200="B",75,IF(T200="C",60,45)))) | BP200: =IF(V200="","",IF(V200="A",90,IF(V200="B",75,IF(V200="C",60,45)))) | BQ200: =IF(X200="","",IF(X200="A",90,IF(X200="B",75,IF(X200="C",60,45)))) | BR200: =IF(Z200="","",IF(Z200="A",90,IF(Z200="B",75,IF(Z200="C",60,45)))) | BS200: =IF(AB200="","",IF(AB200="A",90,IF(AB200="B",75,IF(AB200="C",60,45)))) | BT200: =IF(AD200="","",IF(AD200="A",90,IF(AD200="B",75,IF(AD200="C",60,45)))) | BU200: =IF(AF200="","",IF(AF200="A",90,IF(AF200="B",75,IF(AF200="C",60,45)))) | BV200: =IF(AH200="","",IF(AH200="A",90,IF(AH200="B",75,IF(AH200="C",60,45)))) | BW200: =IF(AJ200="","",IF(AJ200="A",90,IF(AJ200="B",75,IF(AJ200="C",60,45)))) | BX200: =IF(AL200="","",IF(AL200="A",90,IF(AL200="B",75,IF(AL200="C",60,45)))) | BY200: =IF(AN200="","",IF(AN200="A",90,IF(AN200="B",75,IF(AN200="C",60,45)))) | BZ200: =IF(AP200="","",IF(AP200="A",90,IF(AP200="B",75,IF(AP200="C",60,45)))) | CA200: =IF(AR200="","",IF(AR200="A",90,IF(AR200="B",75,IF(AR200="C",60,45)))) | CB200: =IF(AT200="","",IF(AT200="A",90,IF(AT200="B",75,IF(AT200="C",60,45)))) | CC200: =IF(AV200="","",IF(AV200="A",90,IF(AV200="B",75,IF(AV200="C",60,45)))) | CD200: =IF(AX200="","",IF(AX200="A",90,IF(AX200="B",75,IF(AX200="C",60,45))))
BC201: =IF(COUNT(BG201:CD201)=0,"",ROUND(AVERAGE(BG201:CD201),0)) | BD201: =IF(BC201="","",IF(BC201>=85,"A",IF(BC201>=70,"B",IF(BC201>=55,"C","D")))) | BG201: =IF(D201="","",IF(D201="A",90,IF(D201="B",75,IF(D201="C",60,45)))) | BH201: =IF(F201="","",IF(F201="A",90,IF(F201="B",75,IF(F201="C",60,45)))) | BI201: =IF(H201="","",IF(H201="A",90,IF(H201="B",75,IF(H201="C",60,45)))) | BJ201: =IF(J201="","",IF(J201="A",90,IF(J201="B",75,IF(J201="C",60,45)))) | BK201: =IF(L201="","",IF(L201="A",90,IF(L201="B",75,IF(L201="C",60,45)))) | BL201: =IF(N201="","",IF(N201="A",90,IF(N201="B",75,IF(N201="C",60,45)))) | BM201: =IF(P201="","",IF(P201="A",90,IF(P201="B",75,IF(P201="C",60,45)))) | BN201: =IF(R201="","",IF(R201="A",90,IF(R201="B",75,IF(R201="C",60,45)))) | BO201: =IF(T201="","",IF(T201="A",90,IF(T201="B",75,IF(T201="C",60,45)))) | BP201: =IF(V201="","",IF(V201="A",90,IF(V201="B",75,IF(V201="C",60,45)))) | BQ201: =IF(X201="","",IF(X201="A",90,IF(X201="B",75,IF(X201="C",60,45)))) | BR201: =IF(Z201="","",IF(Z201="A",90,IF(Z201="B",75,IF(Z201="C",60,45)))) | BS201: =IF(AB201="","",IF(AB201="A",90,IF(AB201="B",75,IF(AB201="C",60,45)))) | BT201: =IF(AD201="","",IF(AD201="A",90,IF(AD201="B",75,IF(AD201="C",60,45)))) | BU201: =IF(AF201="","",IF(AF201="A",90,IF(AF201="B",75,IF(AF201="C",60,45)))) | BV201: =IF(AH201="","",IF(AH201="A",90,IF(AH201="B",75,IF(AH201="C",60,45)))) | BW201: =IF(AJ201="","",IF(AJ201="A",90,IF(AJ201="B",75,IF(AJ201="C",60,45)))) | BX201: =IF(AL201="","",IF(AL201="A",90,IF(AL201="B",75,IF(AL201="C",60,45)))) | BY201: =IF(AN201="","",IF(AN201="A",90,IF(AN201="B",75,IF(AN201="C",60,45)))) | BZ201: =IF(AP201="","",IF(AP201="A",90,IF(AP201="B",75,IF(AP201="C",60,45)))) | CA201: =IF(AR201="","",IF(AR201="A",90,IF(AR201="B",75,IF(AR201="C",60,45)))) | CB201: =IF(AT201="","",IF(AT201="A",90,IF(AT201="B",75,IF(AT201="C",60,45)))) | CC201: =IF(AV201="","",IF(AV201="A",90,IF(AV201="B",75,IF(AV201="C",60,45)))) | CD201: =IF(AX201="","",IF(AX201="A",90,IF(AX201="B",75,IF(AX201="C",60,45))))
BC202: =IF(COUNT(BG202:CD202)=0,"",ROUND(AVERAGE(BG202:CD202),0)) | BD202: =IF(BC202="","",IF(BC202>=85,"A",IF(BC202>=70,"B",IF(BC202>=55,"C","D")))) | BG202: =IF(D202="","",IF(D202="A",90,IF(D202="B",75,IF(D202="C",60,45)))) | BH202: =IF(F202="","",IF(F202="A",90,IF(F202="B",75,IF(F202="C",60,45)))) | BI202: =IF(H202="","",IF(H202="A",90,IF(H202="B",75,IF(H202="C",60,45)))) | BJ202: =IF(J202="","",IF(J202="A",90,IF(J202="B",75,IF(J202="C",60,45)))) | BK202: =IF(L202="","",IF(L202="A",90,IF(L202="B",75,IF(L202="C",60,45)))) | BL202: =IF(N202="","",IF(N202="A",90,IF(N202="B",75,IF(N202="C",60,45)))) | BM202: =IF(P202="","",IF(P202="A",90,IF(P202="B",75,IF(P202="C",60,45)))) | BN202: =IF(R202="","",IF(R202="A",90,IF(R202="B",75,IF(R202="C",60,45)))) | BO202: =IF(T202="","",IF(T202="A",90,IF(T202="B",75,IF(T202="C",60,45)))) | BP202: =IF(V202="","",IF(V202="A",90,IF(V202="B",75,IF(V202="C",60,45)))) | BQ202: =IF(X202="","",IF(X202="A",90,IF(X202="B",75,IF(X202="C",60,45)))) | BR202: =IF(Z202="","",IF(Z202="A",90,IF(Z202="B",75,IF(Z202="C",60,45)))) | BS202: =IF(AB202="","",IF(AB202="A",90,IF(AB202="B",75,IF(AB202="C",60,45)))) | BT202: =IF(AD202="","",IF(AD202="A",90,IF(AD202="B",75,IF(AD202="C",60,45)))) | BU202: =IF(AF202="","",IF(AF202="A",90,IF(AF202="B",75,IF(AF202="C",60,45)))) | BV202: =IF(AH202="","",IF(AH202="A",90,IF(AH202="B",75,IF(AH202="C",60,45)))) | BW202: =IF(AJ202="","",IF(AJ202="A",90,IF(AJ202="B",75,IF(AJ202="C",60,45)))) | BX202: =IF(AL202="","",IF(AL202="A",90,IF(AL202="B",75,IF(AL202="C",60,45)))) | BY202: =IF(AN202="","",IF(AN202="A",90,IF(AN202="B",75,IF(AN202="C",60,45)))) | BZ202: =IF(AP202="","",IF(AP202="A",90,IF(AP202="B",75,IF(AP202="C",60,45)))) | CA202: =IF(AR202="","",IF(AR202="A",90,IF(AR202="B",75,IF(AR202="C",60,45)))) | CB202: =IF(AT202="","",IF(AT202="A",90,IF(AT202="B",75,IF(AT202="C",60,45)))) | CC202: =IF(AV202="","",IF(AV202="A",90,IF(AV202="B",75,IF(AV202="C",60,45)))) | CD202: =IF(AX202="","",IF(AX202="A",90,IF(AX202="B",75,IF(AX202="C",60,45))))
BC203: =IF(COUNT(BG203:CD203)=0,"",ROUND(AVERAGE(BG203:CD203),0)) | BD203: =IF(BC203="","",IF(BC203>=85,"A",IF(BC203>=70,"B",IF(BC203>=55,"C","D")))) | BG203: =IF(D203="","",IF(D203="A",90,IF(D203="B",75,IF(D203="C",60,45)))) | BH203: =IF(F203="","",IF(F203="A",90,IF(F203="B",75,IF(F203="C",60,45)))) | BI203: =IF(H203="","",IF(H203="A",90,IF(H203="B",75,IF(H203="C",60,45)))) | BJ203: =IF(J203="","",IF(J203="A",90,IF(J203="B",75,IF(J203="C",60,45)))) | BK203: =IF(L203="","",IF(L203="A",90,IF(L203="B",75,IF(L203="C",60,45)))) | BL203: =IF(N203="","",IF(N203="A",90,IF(N203="B",75,IF(N203="C",60,45)))) | BM203: =IF(P203="","",IF(P203="A",90,IF(P203="B",75,IF(P203="C",60,45)))) | BN203: =IF(R203="","",IF(R203="A",90,IF(R203="B",75,IF(R203="C",60,45)))) | BO203: =IF(T203="","",IF(T203="A",90,IF(T203="B",75,IF(T203="C",60,45)))) | BP203: =IF(V203="","",IF(V203="A",90,IF(V203="B",75,IF(V203="C",60,45)))) | BQ203: =IF(X203="","",IF(X203="A",90,IF(X203="B",75,IF(X203="C",60,45)))) | BR203: =IF(Z203="","",IF(Z203="A",90,IF(Z203="B",75,IF(Z203="C",60,45)))) | BS203: =IF(AB203="","",IF(AB203="A",90,IF(AB203="B",75,IF(AB203="C",60,45)))) | BT203: =IF(AD203="","",IF(AD203="A",90,IF(AD203="B",75,IF(AD203="C",60,45)))) | BU203: =IF(AF203="","",IF(AF203="A",90,IF(AF203="B",75,IF(AF203="C",60,45)))) | BV203: =IF(AH203="","",IF(AH203="A",90,IF(AH203="B",75,IF(AH203="C",60,45)))) | BW203: =IF(AJ203="","",IF(AJ203="A",90,IF(AJ203="B",75,IF(AJ203="C",60,45)))) | BX203: =IF(AL203="","",IF(AL203="A",90,IF(AL203="B",75,IF(AL203="C",60,45)))) | BY203: =IF(AN203="","",IF(AN203="A",90,IF(AN203="B",75,IF(AN203="C",60,45)))) | BZ203: =IF(AP203="","",IF(AP203="A",90,IF(AP203="B",75,IF(AP203="C",60,45)))) | CA203: =IF(AR203="","",IF(AR203="A",90,IF(AR203="B",75,IF(AR203="C",60,45)))) | CB203: =IF(AT203="","",IF(AT203="A",90,IF(AT203="B",75,IF(AT203="C",60,45)))) | CC203: =IF(AV203="","",IF(AV203="A",90,IF(AV203="B",75,IF(AV203="C",60,45)))) | CD203: =IF(AX203="","",IF(AX203="A",90,IF(AX203="B",75,IF(AX203="C",60,45))))
BC204: =IF(COUNT(BG204:CD204)=0,"",ROUND(AVERAGE(BG204:CD204),0)) | BD204: =IF(BC204="","",IF(BC204>=85,"A",IF(BC204>=70,"B",IF(BC204>=55,"C","D")))) | BG204: =IF(D204="","",IF(D204="A",90,IF(D204="B",75,IF(D204="C",60,45)))) | BH204: =IF(F204="","",IF(F204="A",90,IF(F204="B",75,IF(F204="C",60,45)))) | BI204: =IF(H204="","",IF(H204="A",90,IF(H204="B",75,IF(H204="C",60,45)))) | BJ204: =IF(J204="","",IF(J204="A",90,IF(J204="B",75,IF(J204="C",60,45)))) | BK204: =IF(L204="","",IF(L204="A",90,IF(L204="B",75,IF(L204="C",60,45)))) | BL204: =IF(N204="","",IF(N204="A",90,IF(N204="B",75,IF(N204="C",60,45)))) | BM204: =IF(P204="","",IF(P204="A",90,IF(P204="B",75,IF(P204="C",60,45)))) | BN204: =IF(R204="","",IF(R204="A",90,IF(R204="B",75,IF(R204="C",60,45)))) | BO204: =IF(T204="","",IF(T204="A",90,IF(T204="B",75,IF(T204="C",60,45)))) | BP204: =IF(V204="","",IF(V204="A",90,IF(V204="B",75,IF(V204="C",60,45)))) | BQ204: =IF(X204="","",IF(X204="A",90,IF(X204="B",75,IF(X204="C",60,45)))) | BR204: =IF(Z204="","",IF(Z204="A",90,IF(Z204="B",75,IF(Z204="C",60,45)))) | BS204: =IF(AB204="","",IF(AB204="A",90,IF(AB204="B",75,IF(AB204="C",60,45)))) | BT204: =IF(AD204="","",IF(AD204="A",90,IF(AD204="B",75,IF(AD204="C",60,45)))) | BU204: =IF(AF204="","",IF(AF204="A",90,IF(AF204="B",75,IF(AF204="C",60,45)))) | BV204: =IF(AH204="","",IF(AH204="A",90,IF(AH204="B",75,IF(AH204="C",60,45)))) | BW204: =IF(AJ204="","",IF(AJ204="A",90,IF(AJ204="B",75,IF(AJ204="C",60,45)))) | BX204: =IF(AL204="","",IF(AL204="A",90,IF(AL204="B",75,IF(AL204="C",60,45)))) | BY204: =IF(AN204="","",IF(AN204="A",90,IF(AN204="B",75,IF(AN204="C",60,45)))) | BZ204: =IF(AP204="","",IF(AP204="A",90,IF(AP204="B",75,IF(AP204="C",60,45)))) | CA204: =IF(AR204="","",IF(AR204="A",90,IF(AR204="B",75,IF(AR204="C",60,45)))) | CB204: =IF(AT204="","",IF(AT204="A",90,IF(AT204="B",75,IF(AT204="C",60,45)))) | CC204: =IF(AV204="","",IF(AV204="A",90,IF(AV204="B",75,IF(AV204="C",60,45)))) | CD204: =IF(AX204="","",IF(AX204="A",90,IF(AX204="B",75,IF(AX204="C",60,45))))

Sheet Student Composition
A1: ANNAPURNA COLLEGE OF FILM AND MEDIA
A3: Select Roll No. | B3: 1
A4: Student Name | B4: =IFERROR(INDEX('Evaluation Sheet'!$A$4:$A$200,MATCH($B$3,'Evaluation Sheet'!$B$4:$B$200,0)),"") -> SRIRAM | D4: Department / Specialisation | E4: =IFERROR(INDEX('Evaluation Sheet'!$C$4:$C$200,MATCH($B$3,'Evaluation Sheet'!$B$4:$B$200,0)),"") -> Cinematography
A5: Final % | B5: =IFERROR(INDEX('Evaluation Sheet'!$BC$4:$BC$200,MATCH($B$3,'Evaluation Sheet'!$B$4:$B$200,0)),"") -> 57.291667 | D5: Final Grade | E5: =IFERROR(INDEX('Evaluation Sheet'!$BD$4:$BD$200,MATCH($B$3,'Evaluation Sheet'!$B$4:$B$200,0)),"") -> C
A6: Portfolio URL | B6: =IFERROR(INDEX('Evaluation Sheet'!$BE$4:$BE$200,MATCH($B$3,'Evaluation Sheet'!$B$4:$B$200,0)),"") -> 0
A7: Foundation
A8: Semester | B8: Screenwriting | C8: Direction | D8: Production | E8: Cine | F8: Sound | G8: Edit
A9: Sem I | B9: =IFERROR(INDEX('Evaluation Sheet'!$D$4:$D$200,MATCH($B$3,'Evaluation Sheet'!$B$4:$B$200,0)),"") -> C | C9: =IFERROR(INDEX('Evaluation Sheet'!$F$4:$F$200,MATCH($B$3,'Evaluation Sheet'!$B$4:$B$200,0)),"") -> C | D9: =IFERROR(INDEX('Evaluation Sheet'!$H$4:$H$200,MATCH($B$3,'Evaluation Sheet'!$B$4:$B$200,0)),"") -> A | E9: =IFERROR(INDEX('Evaluation Sheet'!$J$4:$J$200,MATCH($B$3,'Evaluation Sheet'!$B$4:$B$200,0)),"") -> C | F9: =IFERROR(INDEX('Evaluation Sheet'!$L$4:$L$200,MATCH($B$3,'Evaluation Sheet'!$B$4:$B$200,0)),"") -> D | G9: =IFERROR(INDEX('Evaluation Sheet'!$N$4:$N$200,MATCH($B$3,'Evaluation Sheet'!$B$4:$B$200,0)),"") -> C
A10: Sem II | B10: =IFERROR(INDEX('Evaluation Sheet'!$P$4:$P$200,MATCH($B$3,'Evaluation Sheet'!$B$4:$B$200,0)),"") -> C | C10: =IFERROR(INDEX('Evaluation Sheet'!$R$4:$R$200,MATCH($B$3,'Evaluation Sheet'!$B$4:$B$200,0)),"") -> D | D10: =IFERROR(INDEX('Evaluation Sheet'!$T$4:$T$200,MATCH($B$3,'Evaluation Sheet'!$B$4:$B$200,0)),"") -> D | E10: =IFERROR(INDEX('Evaluation Sheet'!$V$4:$V$200,MATCH($B$3,'Evaluation Sheet'!$B$4:$B$200,0)),"") -> B | F10: =IFERROR(INDEX('Evaluation Sheet'!$X$4:$X$200,MATCH($B$3,'Evaluation Sheet'!$B$4:$B$200,0)),"") -> C | G10: =IFERROR(INDEX('Evaluation Sheet'!$Z$4:$Z$200,MATCH($B$3,'Evaluation Sheet'!$B$4:$B$200,0)),"") -> C
A12: Specialisation Semesters
A13: Semester | B13: Specialisation | C13: Direction | D13: Production | E13: Specialisation Comment | F13: Direction Comment | G13: Production Comment
A14: Sem III | B14: =IFERROR(INDEX('Evaluation Sheet'!$AB$4:$AB$200,MATCH($B$3,'Evaluation Sheet'!$B$4:$B$200,0)),"") -> A | C14: =IFERROR(INDEX('Evaluation Sheet'!$AD$4:$AD$200,MATCH($B$3,'Evaluation Sheet'!$B$4:$B$200,0)),"") -> A | D14: =IFERROR(INDEX('Evaluation Sheet'!$AF$4:$AF$200,MATCH($B$3,'Evaluation Sheet'!$B$4:$B$200,0)),"") -> B
A15: Sem IV | B15: =IFERROR(INDEX('Evaluation Sheet'!$AH$4:$AH$200,MATCH($B$3,'Evaluation Sheet'!$B$4:$B$200,0)),"") -> D | C15: =IFERROR(INDEX('Evaluation Sheet'!$AJ$4:$AJ$200,MATCH($B$3,'Evaluation Sheet'!$B$4:$B$200,0)),"") -> A | D15: =IFERROR(INDEX('Evaluation Sheet'!$AL$4:$AL$200,MATCH($B$3,'Evaluation Sheet'!$B$4:$B$200,0)),"") -> B
A16: Sem V | B16: =IFERROR(INDEX('Evaluation Sheet'!$AN$4:$AN$200,MATCH($B$3,'Evaluation Sheet'!$B$4:$B$200,0)),"") -> C | C16: =IFERROR(INDEX('Evaluation Sheet'!$AP$4:$AP$200,MATCH($B$3,'Evaluation Sheet'!$B$4:$B$200,0)),"") -> A | D16: =IFERROR(INDEX('Evaluation Sheet'!$AR$4:$AR$200,MATCH($B$3,'Evaluation Sheet'!$B$4:$B$200,0)),"") -> D
A17: Sem VI | B17: =IFERROR(INDEX('Evaluation Sheet'!$AT$4:$AT$200,MATCH($B$3,'Evaluation Sheet'!$B$4:$B$200,0)),"") -> D | C17: =IFERROR(INDEX('Evaluation Sheet'!$AV$4:$AV$200,MATCH($B$3,'Evaluation Sheet'!$B$4:$B$200,0)),"") -> C | D17: =IFERROR(INDEX('Evaluation Sheet'!$AX$4:$AX$200,MATCH($B$3,'Evaluation Sheet'!$B$4:$B$200,0)),"") -> C
A19: Final Summary
A20: Creative Comment | B20: =IF($B$3="","",INDEX('Evaluation Sheet'!$AZ$4:$AZ$204,MATCH($B$3,'Evaluation Sheet'!$B$4:$B$204,0))) -> Indicates basic narrative sensitivity, though consistency against professional readiness and final output expectations needs improvement.
A21: Technical Comment | B21: =IF($B$3="","",INDEX('Evaluation Sheet'!$BA$4:$BA$204,MATCH($B$3,'Evaluation Sheet'!$B$4:$B$204,0))) -> Needs stronger control over tool command to meet professional readiness and final output expectations more consistently.
A22: Professional Comment | B22: =IF($B$3="","",INDEX('Evaluation Sheet'!$BB$4:$BB$204,MATCH($B$3,'Evaluation Sheet'!$B$4:$B$204,0))) -> Requires better control over professional attitude to meet professional readiness and final output expectations more consistently.

Sheet Integration Guide
A1: ACFM Integrated Working System - Corrected Specialisation Logic
A2: Specialisation dropdown includes only: Screenwriting, Cinematography, Editing, Sound Design, VFX.
A3: Production is NOT a specialisation. It is retained as a common subject/component for all students.
A4: Direction is also retained as a common subject/component.
A5: Production grade and Production comment dropdowns continue separately for Sem I to Sem VI.
A6: Student Composition pulls the selected specialisation from the Evaluation Sheet.
A7: Use Department / Specialisation column only for the student's chosen elective specialisation.
A9: Google Sheets note
A10: Excel dependent dropdowns may not survive Google conversion. If needed, use this workbook as the master and rebuild dropdowns natively in Google Sheets with Apps Script.
A12: Recommended workflow
A13: 1. Review comments in Comment Matrix.
A14: 2. Choose specialisation in Evaluation Sheet column C.
... A17: 5. Use Student Composition to review individual student output.

Sheet Lists
